[2025-04-16T16:38:14.759+0000] {taskinstance.py:1159} INFO - Dependencies all met for dep_context=non-requeueable deps ti=<TaskInstance: prayer_times_data_pipeline.extract_data_task manual__2025-04-16T16:38:03.001467+00:00 [queued]>
[2025-04-16T16:38:14.765+0000] {taskinstance.py:1159} INFO - Dependencies all met for dep_context=requeueable deps ti=<TaskInstance: prayer_times_data_pipeline.extract_data_task manual__2025-04-16T16:38:03.001467+00:00 [queued]>
[2025-04-16T16:38:14.765+0000] {taskinstance.py:1361} INFO - Starting attempt 1 of 2
[2025-04-16T16:38:14.780+0000] {taskinstance.py:1382} INFO - Executing <Task(PythonOperator): extract_data_task> on 2025-04-16 16:38:03.001467+00:00
[2025-04-16T16:38:14.789+0000] {standard_task_runner.py:57} INFO - Started process 101 to run task
[2025-04-16T16:38:14.792+0000] {standard_task_runner.py:84} INFO - Running: ['airflow', 'tasks', 'run', 'prayer_times_data_pipeline', 'extract_data_task', 'manual__2025-04-16T16:38:03.001467+00:00', '--job-id', '4', '--raw', '--subdir', 'DAGS_FOLDER/Extract.py', '--cfg-path', '/tmp/tmpp8lua5q3']
[2025-04-16T16:38:14.793+0000] {standard_task_runner.py:85} INFO - Job 4: Subtask extract_data_task
[2025-04-16T16:38:14.829+0000] {task_command.py:416} INFO - Running <TaskInstance: prayer_times_data_pipeline.extract_data_task manual__2025-04-16T16:38:03.001467+00:00 [running]> on host d02bd472f10d
[2025-04-16T16:38:15.145+0000] {taskinstance.py:1662} INFO - Exporting env vars: AIRFLOW_CTX_DAG_OWNER='airflow' AIRFLOW_CTX_DAG_ID='prayer_times_data_pipeline' AIRFLOW_CTX_TASK_ID='extract_data_task' AIRFLOW_CTX_EXECUTION_DATE='2025-04-16T16:38:03.001467+00:00' AIRFLOW_CTX_TRY_NUMBER='1' AIRFLOW_CTX_DAG_RUN_ID='manual__2025-04-16T16:38:03.001467+00:00'
[2025-04-16T16:38:15.310+0000] {taskinstance.py:1937} ERROR - Task failed with exception
Traceback (most recent call last):
  File "/home/airflow/.local/lib/python3.8/site-packages/airflow/operators/python.py", line 192, in execute
    return_value = self.execute_callable()
  File "/home/airflow/.local/lib/python3.8/site-packages/airflow/operators/python.py", line 209, in execute_callable
    return self.python_callable(*self.op_args, **self.op_kwargs)
  File "/opt/airflow/dags/Extract.py", line 39, in extract_data
    df_selected.to_csv(file_path, index=False)
  File "/home/airflow/.local/lib/python3.8/site-packages/pandas/core/generic.py", line 3772, in to_csv
    return DataFrameRenderer(formatter).to_csv(
  File "/home/airflow/.local/lib/python3.8/site-packages/pandas/io/formats/format.py", line 1186, in to_csv
    csv_formatter.save()
  File "/home/airflow/.local/lib/python3.8/site-packages/pandas/io/formats/csvs.py", line 240, in save
    with get_handle(
  File "/home/airflow/.local/lib/python3.8/site-packages/pandas/io/common.py", line 737, in get_handle
    check_parent_directory(str(handle))
  File "/home/airflow/.local/lib/python3.8/site-packages/pandas/io/common.py", line 600, in check_parent_directory
    raise OSError(rf"Cannot save file into a non-existent directory: '{parent}'")
OSError: Cannot save file into a non-existent directory: '/opt/airflow/data'
[2025-04-16T16:38:15.326+0000] {taskinstance.py:1400} INFO - Marking task as UP_FOR_RETRY. dag_id=prayer_times_data_pipeline, task_id=extract_data_task, execution_date=20250416T163803, start_date=20250416T163814, end_date=20250416T163815
[2025-04-16T16:38:15.339+0000] {standard_task_runner.py:104} ERROR - Failed to execute job 4 for task extract_data_task (Cannot save file into a non-existent directory: '/opt/airflow/data'; 101)
[2025-04-16T16:38:15.366+0000] {local_task_job_runner.py:228} INFO - Task exited with return code 1
[2025-04-16T16:38:15.382+0000] {taskinstance.py:2778} INFO - 0 downstream tasks scheduled from follow-on schedule check
