[2025-04-15T17:01:42.722+0000] {taskinstance.py:1159} INFO - Dependencies all met for dep_context=non-requeueable deps ti=<TaskInstance: prayer_times_data_pipeline.extract_data_task manual__2025-04-15T16:56:25.760189+00:00 [queued]>
[2025-04-15T17:01:42.730+0000] {taskinstance.py:1159} INFO - Dependencies all met for dep_context=requeueable deps ti=<TaskInstance: prayer_times_data_pipeline.extract_data_task manual__2025-04-15T16:56:25.760189+00:00 [queued]>
[2025-04-15T17:01:42.731+0000] {taskinstance.py:1361} INFO - Starting attempt 2 of 2
[2025-04-15T17:01:42.748+0000] {taskinstance.py:1382} INFO - Executing <Task(PythonOperator): extract_data_task> on 2025-04-15 16:56:25.760189+00:00
[2025-04-15T17:01:42.758+0000] {standard_task_runner.py:57} INFO - Started process 165 to run task
[2025-04-15T17:01:42.784+0000] {standard_task_runner.py:84} INFO - Running: ['airflow', 'tasks', 'run', 'prayer_times_data_pipeline', 'extract_data_task', 'manual__2025-04-15T16:56:25.760189+00:00', '--job-id', '7', '--raw', '--subdir', 'DAGS_FOLDER/Extract.py', '--cfg-path', '/tmp/tmpnheimdcn']
[2025-04-15T17:01:42.792+0000] {standard_task_runner.py:85} INFO - Job 7: Subtask extract_data_task
[2025-04-15T17:01:42.872+0000] {task_command.py:416} INFO - Running <TaskInstance: prayer_times_data_pipeline.extract_data_task manual__2025-04-15T16:56:25.760189+00:00 [running]> on host aead1b99c7cb
[2025-04-15T17:01:43.070+0000] {taskinstance.py:1662} INFO - Exporting env vars: AIRFLOW_CTX_DAG_OWNER='airflow' AIRFLOW_CTX_DAG_ID='prayer_times_data_pipeline' AIRFLOW_CTX_TASK_ID='extract_data_task' AIRFLOW_CTX_EXECUTION_DATE='2025-04-15T16:56:25.760189+00:00' AIRFLOW_CTX_TRY_NUMBER='2' AIRFLOW_CTX_DAG_RUN_ID='manual__2025-04-15T16:56:25.760189+00:00'
[2025-04-15T17:01:43.237+0000] {taskinstance.py:1937} ERROR - Task failed with exception
Traceback (most recent call last):
  File "/home/airflow/.local/lib/python3.8/site-packages/airflow/operators/python.py", line 192, in execute
    return_value = self.execute_callable()
  File "/home/airflow/.local/lib/python3.8/site-packages/airflow/operators/python.py", line 209, in execute_callable
    return self.python_callable(*self.op_args, **self.op_kwargs)
  File "/opt/airflow/dags/Extract.py", line 39, in extract_data
    df_selected.to_csv(file_path, index=False)
  File "/home/airflow/.local/lib/python3.8/site-packages/pandas/core/generic.py", line 3772, in to_csv
    return DataFrameRenderer(formatter).to_csv(
  File "/home/airflow/.local/lib/python3.8/site-packages/pandas/io/formats/format.py", line 1186, in to_csv
    csv_formatter.save()
  File "/home/airflow/.local/lib/python3.8/site-packages/pandas/io/formats/csvs.py", line 240, in save
    with get_handle(
  File "/home/airflow/.local/lib/python3.8/site-packages/pandas/io/common.py", line 859, in get_handle
    handle = open(
PermissionError: [Errno 13] Permission denied: '/prayer_times_march.csv'
[2025-04-15T17:01:43.250+0000] {taskinstance.py:1400} INFO - Marking task as FAILED. dag_id=prayer_times_data_pipeline, task_id=extract_data_task, execution_date=20250415T165625, start_date=20250415T170142, end_date=20250415T170143
[2025-04-15T17:01:43.266+0000] {standard_task_runner.py:104} ERROR - Failed to execute job 7 for task extract_data_task ([Errno 13] Permission denied: '/prayer_times_march.csv'; 165)
[2025-04-15T17:01:43.298+0000] {local_task_job_runner.py:228} INFO - Task exited with return code 1
[2025-04-15T17:01:43.324+0000] {taskinstance.py:2778} INFO - 0 downstream tasks scheduled from follow-on schedule check
