[2025-04-16T15:31:32.254+0000] {taskinstance.py:1159} INFO - Dependencies all met for dep_context=non-requeueable deps ti=<TaskInstance: prayer_times_data_pipeline.extract_data_task scheduled__2025-04-15T06:00:00+00:00 [queued]>
[2025-04-16T15:31:32.260+0000] {taskinstance.py:1159} INFO - Dependencies all met for dep_context=requeueable deps ti=<TaskInstance: prayer_times_data_pipeline.extract_data_task scheduled__2025-04-15T06:00:00+00:00 [queued]>
[2025-04-16T15:31:32.261+0000] {taskinstance.py:1361} INFO - Starting attempt 1 of 2
[2025-04-16T15:31:32.278+0000] {taskinstance.py:1382} INFO - Executing <Task(PythonOperator): extract_data_task> on 2025-04-15 06:00:00+00:00
[2025-04-16T15:31:32.287+0000] {standard_task_runner.py:57} INFO - Started process 80 to run task
[2025-04-16T15:31:32.292+0000] {standard_task_runner.py:84} INFO - Running: ['airflow', 'tasks', 'run', 'prayer_times_data_pipeline', 'extract_data_task', 'scheduled__2025-04-15T06:00:00+00:00', '--job-id', '11', '--raw', '--subdir', 'DAGS_FOLDER/Extract.py', '--cfg-path', '/tmp/tmpu449nash']
[2025-04-16T15:31:32.294+0000] {standard_task_runner.py:85} INFO - Job 11: Subtask extract_data_task
[2025-04-16T15:31:32.367+0000] {task_command.py:416} INFO - Running <TaskInstance: prayer_times_data_pipeline.extract_data_task scheduled__2025-04-15T06:00:00+00:00 [running]> on host aead1b99c7cb
[2025-04-16T15:31:32.615+0000] {taskinstance.py:1662} INFO - Exporting env vars: AIRFLOW_CTX_DAG_OWNER='airflow' AIRFLOW_CTX_DAG_ID='prayer_times_data_pipeline' AIRFLOW_CTX_TASK_ID='extract_data_task' AIRFLOW_CTX_EXECUTION_DATE='2025-04-15T06:00:00+00:00' AIRFLOW_CTX_TRY_NUMBER='1' AIRFLOW_CTX_DAG_RUN_ID='scheduled__2025-04-15T06:00:00+00:00'
[2025-04-16T15:31:32.848+0000] {taskinstance.py:1937} ERROR - Task failed with exception
Traceback (most recent call last):
  File "/home/airflow/.local/lib/python3.8/site-packages/airflow/operators/python.py", line 192, in execute
    return_value = self.execute_callable()
  File "/home/airflow/.local/lib/python3.8/site-packages/airflow/operators/python.py", line 209, in execute_callable
    return self.python_callable(*self.op_args, **self.op_kwargs)
  File "/opt/airflow/dags/Extract.py", line 39, in extract_data
    df_selected.to_csv(file_path, index=False)
  File "/home/airflow/.local/lib/python3.8/site-packages/pandas/core/generic.py", line 3772, in to_csv
    return DataFrameRenderer(formatter).to_csv(
  File "/home/airflow/.local/lib/python3.8/site-packages/pandas/io/formats/format.py", line 1186, in to_csv
    csv_formatter.save()
  File "/home/airflow/.local/lib/python3.8/site-packages/pandas/io/formats/csvs.py", line 240, in save
    with get_handle(
  File "/home/airflow/.local/lib/python3.8/site-packages/pandas/io/common.py", line 859, in get_handle
    handle = open(
PermissionError: [Errno 13] Permission denied: '/prayer_times_march.csv'
[2025-04-16T15:31:32.871+0000] {taskinstance.py:1400} INFO - Marking task as UP_FOR_RETRY. dag_id=prayer_times_data_pipeline, task_id=extract_data_task, execution_date=20250415T060000, start_date=20250416T153132, end_date=20250416T153132
[2025-04-16T15:31:32.886+0000] {standard_task_runner.py:104} ERROR - Failed to execute job 11 for task extract_data_task ([Errno 13] Permission denied: '/prayer_times_march.csv'; 80)
[2025-04-16T15:31:32.905+0000] {local_task_job_runner.py:228} INFO - Task exited with return code 1
[2025-04-16T15:31:32.926+0000] {taskinstance.py:2778} INFO - 0 downstream tasks scheduled from follow-on schedule check
[2025-04-16T16:38:09.614+0000] {taskinstance.py:1159} INFO - Dependencies all met for dep_context=non-requeueable deps ti=<TaskInstance: prayer_times_data_pipeline.extract_data_task scheduled__2025-04-15T06:00:00+00:00 [queued]>
[2025-04-16T16:38:09.621+0000] {taskinstance.py:1159} INFO - Dependencies all met for dep_context=requeueable deps ti=<TaskInstance: prayer_times_data_pipeline.extract_data_task scheduled__2025-04-15T06:00:00+00:00 [queued]>
[2025-04-16T16:38:09.622+0000] {taskinstance.py:1361} INFO - Starting attempt 1 of 2
[2025-04-16T16:38:09.642+0000] {taskinstance.py:1382} INFO - Executing <Task(PythonOperator): extract_data_task> on 2025-04-15 06:00:00+00:00
[2025-04-16T16:38:09.663+0000] {standard_task_runner.py:57} INFO - Started process 88 to run task
[2025-04-16T16:38:09.670+0000] {standard_task_runner.py:84} INFO - Running: ['airflow', 'tasks', 'run', 'prayer_times_data_pipeline', 'extract_data_task', 'scheduled__2025-04-15T06:00:00+00:00', '--job-id', '3', '--raw', '--subdir', 'DAGS_FOLDER/Extract.py', '--cfg-path', '/tmp/tmp0jaonohy']
[2025-04-16T16:38:09.672+0000] {standard_task_runner.py:85} INFO - Job 3: Subtask extract_data_task
[2025-04-16T16:38:09.785+0000] {task_command.py:416} INFO - Running <TaskInstance: prayer_times_data_pipeline.extract_data_task scheduled__2025-04-15T06:00:00+00:00 [running]> on host d02bd472f10d
[2025-04-16T16:38:10.301+0000] {taskinstance.py:1662} INFO - Exporting env vars: AIRFLOW_CTX_DAG_OWNER='airflow' AIRFLOW_CTX_DAG_ID='prayer_times_data_pipeline' AIRFLOW_CTX_TASK_ID='extract_data_task' AIRFLOW_CTX_EXECUTION_DATE='2025-04-15T06:00:00+00:00' AIRFLOW_CTX_TRY_NUMBER='1' AIRFLOW_CTX_DAG_RUN_ID='scheduled__2025-04-15T06:00:00+00:00'
[2025-04-16T16:38:10.630+0000] {taskinstance.py:1937} ERROR - Task failed with exception
Traceback (most recent call last):
  File "/home/airflow/.local/lib/python3.8/site-packages/airflow/operators/python.py", line 192, in execute
    return_value = self.execute_callable()
  File "/home/airflow/.local/lib/python3.8/site-packages/airflow/operators/python.py", line 209, in execute_callable
    return self.python_callable(*self.op_args, **self.op_kwargs)
  File "/opt/airflow/dags/Extract.py", line 39, in extract_data
    df_selected.to_csv(file_path, index=False)
  File "/home/airflow/.local/lib/python3.8/site-packages/pandas/core/generic.py", line 3772, in to_csv
    return DataFrameRenderer(formatter).to_csv(
  File "/home/airflow/.local/lib/python3.8/site-packages/pandas/io/formats/format.py", line 1186, in to_csv
    csv_formatter.save()
  File "/home/airflow/.local/lib/python3.8/site-packages/pandas/io/formats/csvs.py", line 240, in save
    with get_handle(
  File "/home/airflow/.local/lib/python3.8/site-packages/pandas/io/common.py", line 737, in get_handle
    check_parent_directory(str(handle))
  File "/home/airflow/.local/lib/python3.8/site-packages/pandas/io/common.py", line 600, in check_parent_directory
    raise OSError(rf"Cannot save file into a non-existent directory: '{parent}'")
OSError: Cannot save file into a non-existent directory: '/opt/airflow/data'
[2025-04-16T16:38:10.644+0000] {taskinstance.py:1400} INFO - Marking task as UP_FOR_RETRY. dag_id=prayer_times_data_pipeline, task_id=extract_data_task, execution_date=20250415T060000, start_date=20250416T163809, end_date=20250416T163810
[2025-04-16T16:38:10.657+0000] {standard_task_runner.py:104} ERROR - Failed to execute job 3 for task extract_data_task (Cannot save file into a non-existent directory: '/opt/airflow/data'; 88)
[2025-04-16T16:38:10.690+0000] {local_task_job_runner.py:228} INFO - Task exited with return code 1
[2025-04-16T16:38:10.707+0000] {taskinstance.py:2778} INFO - 0 downstream tasks scheduled from follow-on schedule check
