[2025-04-15T17:01:37.897+0000] {taskinstance.py:1159} INFO - Dependencies all met for dep_context=non-requeueable deps ti=<TaskInstance: prayer_times_data_pipeline.extract_data_task scheduled__2025-04-14T06:00:00+00:00 [queued]>
[2025-04-15T17:01:37.903+0000] {taskinstance.py:1159} INFO - Dependencies all met for dep_context=requeueable deps ti=<TaskInstance: prayer_times_data_pipeline.extract_data_task scheduled__2025-04-14T06:00:00+00:00 [queued]>
[2025-04-15T17:01:37.904+0000] {taskinstance.py:1361} INFO - Starting attempt 2 of 2
[2025-04-15T17:01:37.921+0000] {taskinstance.py:1382} INFO - Executing <Task(PythonOperator): extract_data_task> on 2025-04-14 06:00:00+00:00
[2025-04-15T17:01:37.929+0000] {standard_task_runner.py:57} INFO - Started process 154 to run task
[2025-04-15T17:01:37.932+0000] {standard_task_runner.py:84} INFO - Running: ['airflow', 'tasks', 'run', 'prayer_times_data_pipeline', 'extract_data_task', 'scheduled__2025-04-14T06:00:00+00:00', '--job-id', '6', '--raw', '--subdir', 'DAGS_FOLDER/Extract.py', '--cfg-path', '/tmp/tmp61vzrqp2']
[2025-04-15T17:01:37.934+0000] {standard_task_runner.py:85} INFO - Job 6: Subtask extract_data_task
[2025-04-15T17:01:37.981+0000] {task_command.py:416} INFO - Running <TaskInstance: prayer_times_data_pipeline.extract_data_task scheduled__2025-04-14T06:00:00+00:00 [running]> on host aead1b99c7cb
[2025-04-15T17:01:38.193+0000] {taskinstance.py:1662} INFO - Exporting env vars: AIRFLOW_CTX_DAG_OWNER='airflow' AIRFLOW_CTX_DAG_ID='prayer_times_data_pipeline' AIRFLOW_CTX_TASK_ID='extract_data_task' AIRFLOW_CTX_EXECUTION_DATE='2025-04-14T06:00:00+00:00' AIRFLOW_CTX_TRY_NUMBER='2' AIRFLOW_CTX_DAG_RUN_ID='scheduled__2025-04-14T06:00:00+00:00'
[2025-04-15T17:01:38.469+0000] {taskinstance.py:1937} ERROR - Task failed with exception
Traceback (most recent call last):
  File "/home/airflow/.local/lib/python3.8/site-packages/airflow/operators/python.py", line 192, in execute
    return_value = self.execute_callable()
  File "/home/airflow/.local/lib/python3.8/site-packages/airflow/operators/python.py", line 209, in execute_callable
    return self.python_callable(*self.op_args, **self.op_kwargs)
  File "/opt/airflow/dags/Extract.py", line 39, in extract_data
    df_selected.to_csv(file_path, index=False)
  File "/home/airflow/.local/lib/python3.8/site-packages/pandas/core/generic.py", line 3772, in to_csv
    return DataFrameRenderer(formatter).to_csv(
  File "/home/airflow/.local/lib/python3.8/site-packages/pandas/io/formats/format.py", line 1186, in to_csv
    csv_formatter.save()
  File "/home/airflow/.local/lib/python3.8/site-packages/pandas/io/formats/csvs.py", line 240, in save
    with get_handle(
  File "/home/airflow/.local/lib/python3.8/site-packages/pandas/io/common.py", line 859, in get_handle
    handle = open(
PermissionError: [Errno 13] Permission denied: '/prayer_times_march.csv'
[2025-04-15T17:01:38.486+0000] {taskinstance.py:1400} INFO - Marking task as FAILED. dag_id=prayer_times_data_pipeline, task_id=extract_data_task, execution_date=20250414T060000, start_date=20250415T170137, end_date=20250415T170138
[2025-04-15T17:01:38.500+0000] {standard_task_runner.py:104} ERROR - Failed to execute job 6 for task extract_data_task ([Errno 13] Permission denied: '/prayer_times_march.csv'; 154)
[2025-04-15T17:01:38.548+0000] {local_task_job_runner.py:228} INFO - Task exited with return code 1
[2025-04-15T17:01:38.566+0000] {taskinstance.py:2778} INFO - 0 downstream tasks scheduled from follow-on schedule check
